Workbook

Sheet Özet
B1: Salzburg ve Çevresi – IT & Cyber Security İş İlanları (CANLI TARAMA)
B2: Aday: Evren Selvi · Canlı tarama 27.09.2026 · karriere.at + LinkedIn + Red Bull resmi portalı + ACP portalı · 122 aktif ilan, her linki açılıp başlığı eşleştirildi
B4: ADAY PROFİLİ (CV'den)
B5: Konum | C5: Salzburg, Avusturya – hemen başlayabilir; Avusturya'da çalışma izni var
B6: Deneyim | C6: 15+ yıl kurumsal IT: IT Manager (Inditex, 2021–23) · ISMS Executive (2016–21) · Senior IT Project Resp. (2012–16) · M&S/GAP Retail IT Ops (2007–12)
B7: Güçlü yönler | C7: 200+ mağaza / 17.000 cihaz IT operasyonu · ISO 27001 ISMS (5 yıl) · AD / Windows Server · Hyper-V/Proxmox · backup/DR · VLAN/VPN/firewall · ITIL · bütçe & tedarikçi yönetimi
B8: Sertifikalar | C8: ISO 27001 Internal Auditor · ITIL (Axelos) · MCDBA · SQL Server 2005/2008 · Excel Expert · Linux eğitimi (İTÜ)
B9: Diller | C9: Türkçe (ana dil) · İngilizce (ileri) · Almanca B1/B2
B10: Aranan alanlar (tek liste) | C10: IT altyapı/operasyon · IT yönetimi · ISMS / Information Security · Cyber Security · IT servis (ITIL) · IT proje · sistem/ağ yönetimi · IT destek
B12: PUANLAMA AĞIRLIKLARI (sarı hücreler değiştirilebilir – tüm puanlar otomatik güncellenir)
B13: Kriter | C13: Ağırlık | D13: Açıklama
B14: Teknik uyum | C14: 0.3 | D14: İlan metnindeki beceriler ↔ CV: ISO 27001/ISMS, ITIL, AD/Windows Server, sanallaştırma, backup/DR, ağ/firewall, SQL, proje/tedarikçi/bütçe yönetimi. Eksikler (Azure, SIEM, scripting, SAP…) puan düşürür
B15: Deneyim / kıdem uyumu | C15: 0.15 | D15: 15+ yıl, yönetici seviyesi; junior / 1st-level roller düşük (overqualified)
B16: Dil uyumu | C16: 0.3 | D16: İlanın gerçek dil şartı metinden okundu (skala aşağıda). 27.09 güncellemesi: İngilizce öncelikli – ağırlık %20→%30, Almanca isteyen ilanların puanı düşürüldü
B17: Sektör / kültür | C17: 0.05 | D17: Perakende / FMCG / çok lokasyonlu kurumsal = artı
B18: Lokasyon / ulaşım | C18: 0.1 | D18: Salzburg merkezden: ≤30 dk = 5 · 30–45 = 4 · 45–60 = 3 · 60–90 = 2
B19: Maaş / kariyer | C19: 0.1 | D19: İlandaki yıllık brüt maaş (14 maaş). Sadece KV asgarisi yazıyorsa ceza yok (3–3,5)
B20: Toplam (100% olmalı) | C20: =SUM(C14:C19) -> 1
B22: DİL KODLARI (ilan metninden otomatik okundu – 'Almanca şartı' sütununda alıntı var)
B23: Kod | C23: Puan (1–5) | D23: Anlamı
B24: EN | C24: 5 | D24: İngilizce ilan, Almanca şartı yok
B25: EN (+DE artı) | C25: 5 | D25: İngilizce yeterli; Almanca sadece 'von Vorteil / a plus'
B26: EN+DE | C26: 3,5 | D26: İngilizce ilan, Almanca da isteniyor (seviye belirtilmemiş)
B27: DE+EN | C27: 2 | D27: Almanca ilan; Almanca seviyesi belirtilmemiş + İngilizce isteniyor
B28: EN+DE (akıcı DE) | C28: 1,5 | D28: İngilizce ilan ama akıcı/çok iyi Almanca şart
B29: DE | C29: 1,5 | D29: Almanca ilan, seviye belirtilmemiş, İngilizce yok
B30: DE C1 | C30: 1 | D30: 'Sehr gute / fließende / ausgezeichnete Deutschkenntnisse' ya da C1 – akıcı Almanca olmadan çok zor
B31: Türkçe | C31: +1 | D31: İlanda Türkçe geçerse +1 (bu taramada Türkçe isteyen IT ilanı çıkmadı)
B33: İSTATİSTİKLER (canlı formüller)
B34: Toplam aktif ilan (linki canlı test edildi) | C34: =COUNTA(İlanlar!$C$5:$C$126) -> 122
B35: A – Hemen başvur: İngilizce yeterli + uyum ≥70% | C35: =COUNTIF(İlanlar!$AB$5:$AB$126,"A*") -> 16
B36: B – Başvur: uyum ≥70% ama Almanca gerekli / İngilizce 60–69% | C36: =COUNTIF(İlanlar!$AB$5:$AB$126,"B*") -> 11
B37: C – Opsiyonel | C37: =COUNTIF(İlanlar!$AB$5:$AB$126,"C*") -> 95
B38: Cyber Security / ISMS ilanları | C38: =COUNTIF(İlanlar!$F$5:$F$126,"Cyber*") -> 25
B39: İngilizce yeterli (EN / EN +DE artı) | C39: =COUNTIF(İlanlar!$G$5:$G$126,"EN")+COUNTIF(İlanlar!$G$5:$G$126,"EN (+DE artı)") -> 16
B40: İngilizce + Almanca (EN+DE / DE+EN) | C40: =COUNTIF(İlanlar!$G$5:$G$126,"EN+DE")+COUNTIF(İlanlar!$G$5:$G$126,"DE+EN")+COUNTIF(İlanlar!$G$5:$G$126,"EN+DE (akıcı DE)") -> 24
B41: Sadece Almanca (DE / DE C1) | C41: =COUNTIF(İlanlar!$G$5:$G$126,"DE")+COUNTIF(İlanlar!$G$5:$G$126,"DE C1") -> 82
B42: Ortalama uyum | C42: =AVERAGE(İlanlar!$Z$5:$Z$126) -> 0.63377049
B43: En yüksek uyum | C43: =MAX(İlanlar!$Z$5:$Z$126) -> 0.91
B44: Taramada bulunup profil/ulaşım nedeniyle elenen | C44: 114
...

Sheet İlanlar
A1: Aktif İş İlanları – Salzburg & Çevresi (IT + Cyber Security tek liste, uyuma göre sıralı) · canlı tarama 27.09.2026
A2: Tüm linkler açılıp test edildi · Mavi = düzenlenebilir puan (1–5) · Filtre: F (alan), G (dil), AB (öncelik)
T3: PUANLAR (1–5)
A4: No | B4: Firma | C4: Pozisyon | D4: Lokasyon | E4: Salzburg'dan ulaşım | F4: Alan | G4: Çalışma dili | H4: Almanca şartı (ilandan alıntı) | I4: Türkçe | J4: Kıdem | K4: Maaş (ilandan) | L4: Yayın / güncelleme tarihi | M4: Kaynak | N4: İLAN LİNKİ (canlı test ✓) | O4: Link kontrol | P4: Yedek link(ler) (aynı ilan, test ✓) | Q4: Temel gereksinimler (ilandan) | R4: CV ile eşleşenler | S4: Eksikler / riskler | T4: Teknik | U4: Deneyim | V4: Dil | W4: Sektör | X4: Lokasyon | Y4: Maaş | Z4: Uyum % | AA4: Sıra | AB4: Öncelik | AC4: Önerilen aksiyon | AD4: Firmanın tüm açık ilanları | AE4: Sıralama skoru (İngilizce önce)
A5: 1 | B5: Red Bull | C5: IT Sales Applications Project Manager | D5: Elsbethen | E5: ≤30 dk (Salzburg / yakın çevre) | F5: IT proje yönetimi | G5: EN (+DE artı) | H5: PMP or PRINCE2) is considered an advantage Fluent English skills, German is a plus At least five years of experience in delivering IT projects | I5: — | J5: Kıdemli / yönetici | K5: Sadece KV asgarisi: ~€33k/yıl (ab 2.362 € monatlich) – gerçek maaş belirtilmemiş, genelde üstünde | L5: 2026-09-27 | M5: Red Bull resmi | N5: https://jobs.redbull.com/at-de/it-sales-applications-project-manager-ref33553h | O5: 27.09.2026 14:14 · HTTP 200 · AÇIK | P5: https://www.karriere.at/jobs/7867234 | Q5: Vollzeit IT Sales Applications Project Manager Elsbethen, Österreich Apply now As part of our Sales Applications Team, this role involves shaping the future of our business application landscape. By leading strategic IT initiatives across Sales, Finance, and eCommerce, you'll drive digital transformation, enable business growth, and deliver solutions that create value on a global scale. As an IT Sales Applications Pr… | R5: ITIL / ITSM, Proje yönetimi, Bütçe, Risk yönetimi, Politika / uyum | S5: SAP, İş uygulaması alanı (CRM/ERP/Legal/ServiceNow…) | T5: 4 | U5: 5 | V5: 5 | W5: 5 | X5: 5 | Y5: 3.5 | Z5: =ROUND((T5*Özet!$C$14+U5*Özet!$C$15+V5*Özet!$C$16+W5*Özet!$C$17+X5*Özet!$C$18+Y5*Özet!$C$19)/5,4) -> 0.91 | AA5: =RANK(AE5,$AE$5:$AE$126)+COUNTIF($AE$5:AE5,AE5)-1 -> 1 | AB5: =IF(AND(OR(G5="EN",G5="EN (+DE artı)"),Z5>=0.7),"A – Hemen başvur (İngilizce)",IF(Z5>=0.7,"B – Başvur (Almanca gerekli)",IF(AND(OR(G5="EN",G5="EN (+DE artı)"),Z5>=0.6),"B – Başvur (İngilizce)","C – Opsiyonel"))) -> A – Hemen başvur (İngilizce) | AC5: İngilizce CV + ön yazı ile başvur | AD5: https://www.karriere.at/f/red-bull | AE5: =Z5+IF(OR(G5="EN",G5="EN (+DE artı)"),1,0) -> 1.91
A6: 2 | B6: SKIDATA GmbH | C6: Senior Project Manager - Delivery Execution & Multi-Team Governance (m/f/d) | D6: Wals | E6: ≤30 dk (Salzburg / yakın çevre) | F6: IT proje yönetimi | G6: EN | H6: Almanca şartı belirtilmemiş | I6: — | J6: Kıdemli / yönetici | K6: İlanda belirtilmemiş | L6: 2026-09-20 | M6: karriere.at | N6: https://www.karriere.at/jobs/7854275 | O6: 27.09.2026 14:14 · HTTP 200 · AÇIK | P6: https://www.linkedin.com/jobs/view/4446017342 | Q6: 10+ years of project or program management experience. Proven track record in large-scale software, cloud, or product delivery programs. Strong experience in delivery governance, execution control, and stakeholder management. Demonstrated ability to coordinate multiple development teams and complex dependencies. Excellent communication and executive reporting skills. Experience working in Agile, Waterfall, or hybrid… | R6: Ekip liderliği, Risk yönetimi, Politika / uyum | S6: 10+ yıl büyük yazılım/ürün teslimat programı yönetimi şartı | T6: 3.5 | U6: 5 | V6: 5 | W6: 4 | X6: 5 | Y6: 3.5 | Z6: =ROUND((T6*Özet!$C$14+U6*Özet!$C$15+V6*Özet!$C$16+W6*Özet!$C$17+X6*Özet!$C$18+Y6*Özet!$C$19)/5,4) -> 0.87 | AA6: =RANK(AE6,$AE$5:$AE$126)+COUNTIF($AE$5:AE6,AE6)-1 -> 2 | AB6: =IF(AND(OR(G6="EN",G6="EN (+DE artı)"),Z6>=0.7),"A – Hemen başvur (İngilizce)",IF(Z6>=0.7,"B – Başvur (Almanca gerekli)",IF(AND(OR(G6="EN",G6="EN (+DE artı)"),Z6>=0.6),"B – Başvur (İngilizce)","C – Opsiyonel"))) -> A – Hemen başvur (İngilizce) | AC6: İngilizce CV + ön yazı ile başvur | AD6: https://www.karriere.at/f/skidata | AE6: =Z6+IF(OR(G6="EN",G6="EN (+DE artı)"),1,0) -> 1.87
A7: 3 | B7: Red Bull | C7: IT Project Manager - Legal Solutions | D7: Elsbethen | E7: ≤30 dk (Salzburg / yakın çevre) | F7: IT proje yönetimi | G7: EN (+DE artı) | H7: language skills are an advantage At least three years of experience m | I7: — | J7: Kıdemli / yönetici | K7: Sadece KV asgarisi: ~€33k/yıl (ab 2.362 € monatlich) – gerçek maaş belirtilmemiş, genelde üstünde | L7: 2026-09-21 | M7: Red Bull resmi | N7: https://jobs.redbull.com/at-de/it-project-manager-legal-solutions-ref33927j | O7: 27.09.2026 14:13 · HTTP 200 · AÇIK | P7: https://www.karriere.at/jobs/7875472 https://www.linkedin.com/jobs/view/4466092730 https://www.linkedin.com/jobs/view/4472017663 | Q7: Vollzeit IT Project Manager - Legal Solutions Elsbethen, Österreich Apply now Are you ready to turn complex challenges into smart, scalable solutions and make things happen? As a technically savvy Project Manager with an analytical mindset and a passion for holistic business solutions, you'll advance the digitalisation of the Legal business domain. Join our Cross Functional & Legal Projects team (sitting in Elsbethen… | R7: ITIL / ITSM, Proje yönetimi, Tedarikçi yönetimi, Bütçe, Ekip liderliği, Risk yönetimi, Politika / uyum | S7: ANA ŞART: İş uygulaması alanı (CRM/ERP/Legal/ServiceNow…), ANA ŞART: AI / ML | T7: 3 | U7: 5 | V7: 5 | W7: 5 | X7: 5 | Y7: 3.5 | Z7: =ROUND((T7*Özet!$C$14+U7*Özet!$C$15+V7*Özet!$C$16+W7*Özet!$C$17+X7*Özet!$C$18+Y7*Özet!$C$19)/5,4) -> 0.85 | AA7: =RANK(AE7,$AE$5:$AE$126)+COUNTIF($AE$5:AE7,AE7)-1 -> 3 | AB7: =IF(AND(OR(G7="EN",G7="EN (+DE artı)"),Z7>=0.7),"A – Hemen başvur (İngilizce)",IF(Z7>=0.7,"B – Başvur (Almanca gerekli)",IF(AND(OR(G7="EN",G7="EN (+DE artı)"),Z7>=0.6),"B – Başvur (İngilizce)","C – Opsiyonel"))) -> A – Hemen başvur (İngilizce) | AC7: İngilizce CV + ön yazı ile başvur | AD7: https://www.karriere.at/f/red-bull | AE7: =Z7+IF(OR(G7="EN",G7="EN (+DE artı)"),1,0) -> 1.85
A8: 4 | B8: Red Bull | C8: Project Manager (Portfolio Management) | D8: Elsbethen | E8: ≤30 dk (Salzburg / yakın çevre) | F8: IT proje yönetimi | G8: EN | H8: Almanca şartı belirtilmemiş | I8: — | J8: Kıdemli / yönetici | K8: Sadece KV asgarisi: ~€33k/yıl (ab 2.362 € monatlich) – gerçek maaş belirtilmemiş, genelde üstünde | L8: 2026-09-26 | M8: Red Bull resmi | N8: https://jobs.redbull.com/at-de/project-manager-portfolio-management-ref34093e | O8: 27.09.2026 14:13 · HTTP 200 · AÇIK | P8: https://www.karriere.at/jobs/7878376 https://www.linkedin.com/jobs/view/4468809516 | Q8: Vollzeit Project Manager (Portfolio Management) Elsbethen, Österreich Apply now We are seeking an experienced and proactive Project Manager to lead strategic initiatives within the Supply Chain domain, operating as part of the Portfolio Management function in the CFO organization. In this pivotal role, you will be involved across the end-to-end supply chain operations and help to shape the evolution of our global sup… | R8: ITIL / ITSM, Proje yönetimi, Bütçe, Ekip liderliği, Risk yönetimi, Microsoft ortamı | S8: DİKKAT: IT rolü değil – Supply Chain / CFO portföy PMO (Red Bull'da 'Finance' fonksiyonu); supply chain alan bilgisi | T8: 3 | U8: 5 | V8: 5 | W8: 5 | X8: 5 | Y8: 3.5 | Z8: =ROUND((T8*Özet!$C$14+U8*Özet!$C$15+V8*Özet!$C$16+W8*Özet!$C$17+X8*Özet!$C$18+Y8*Özet!$C$19)/5,4) -> 0.85 | AA8: =RANK(AE8,$AE$5:$AE$126)+COUNTIF($AE$5:AE8,AE8)-1 -> 4 | AB8: =IF(AND(OR(G8="EN",G8="EN (+DE artı)"),Z8>=0.7),"A – Hemen başvur (İngilizce)",IF(Z8>=0.7,"B – Başvur (Almanca gerekli)",IF(AND(OR(G8="EN",G8="EN (+DE artı)"),Z8>=0.6),"B – Başvur (İngilizce)","C – Opsiyonel"))) -> A – Hemen başvur (İngilizce) | AC8: İngilizce CV + ön yazı ile başvur | AD8: https://www.karriere.at/f/red-bull | AE8: =Z8+IF(OR(G8="EN",G8="EN (+DE artı)"),1,0) -> 1.85
A9: 5 | B9: Red Bull | C9: Application Security Service Manager | D9: Elsbethen | E9: ≤30 dk (Salzburg / yakın çevre) | F9: Cyber Security – yönetişim / ISMS | G9: EN (+DE artı) | H9: Informatics, or equivalent experience Fluent English skills, German is a plus At least three years of experience in application security, | I9: — | J9: Kıdemli / yönetici | K9: Sadece KV asgarisi: ~€35k/yıl (ab 2.535 € monatlich) – gerçek maaş belirtilmemiş, genelde üstünde | L9: 2026-09-26 | M9: Red Bull resmi | N9: https://jobs.redbull.com/at-de/application-security-service-manager-ref33475n | O9: 27.09.2026 14:13 · HTTP 200 · AÇIK | P9: https://www.karriere.at/jobs/7865764 https://www.linkedin.com/jobs/view/4459310475 | Q9: Vollzeit Application Security Service Manager Elsbethen, Österreich Apply now Are you ready to help shape the future of secure software development at Red Bull? As part of our Digital Security team, you will play a key role in safeguarding custom software development and advancing our application security capabilities. Partnering closely with security peers, engineering, development, and product teams, you will drive… | R9: Tedarikçi yönetimi, Bütçe, Ekip liderliği, Politika / uyum | S9: ANA ŞART: Programlama, ANA ŞART: Pentest, ANA ŞART: Application security / secure SDLC, AI / ML | T9: 3 | U9: 5 | V9: 5 | W9: 5 | X9: 5 | Y9: 3.5 | Z9: =ROUND((T9*Özet!$C$14+U9*Özet!$C$15+V9*Özet!$C$16+W9*Özet!$C$17+X9*Özet!$C$18+Y9*Özet!$C$19)/5,4) -> 0.85 | AA9: =RANK(AE9,$AE$5:$AE$126)+COUNTIF($AE$5:AE9,AE9)-1 -> 5 | AB9: =IF(AND(OR(G9="EN",G9="EN (+DE artı)"),Z9>=0.7),"A – Hemen başvur (İngilizce)",IF(Z9>=0.7,"B – Başvur (Almanca gerekli)",IF(AND(OR(G9="EN",G9="EN (+DE artı)"),Z9>=0.6),"B – Başvur (İngilizce)","C – Opsiyonel"))) -> A – Hemen başvur (İngilizce) | AC9: İngilizce CV + ön yazı ile başvur | AD9: https://www.karriere.at/f/red-bull | AE9: =Z9+IF(OR(G9="EN",G9="EN (+DE artı)"),1,0) -> 1.85
A10: 6 | B10: Red Bull | C10: IT Team Manager - Global Field Sales Applications | D10: Elsbethen | E10: ≤30 dk (Salzburg / yakın çevre) | F10: IT yönetimi / liderlik | G10: EN (+DE artı) | H10: study or equivalent practical experience Fluent English skills, German is a plus At least 5 years of working experience with field sales app | I10: — | J10: Kıdemli / yönetici | K10: Sadece KV asgarisi: ~€40k/yıl (ab 2.879 € monatlich) – gerçek maaş belirtilmemiş, genelde üstünde | L10: 2026-09-21 | M10: Red Bull resmi | N10: https://jobs.redbull.com/at-de/elsbethen-it-manager-global-field-sales-applications-ref31287p | O10: 27.09.2026 14:14 · HTTP 200 · AÇIK | P10: https://www.karriere.at/jobs/7879372 | Q10: Vollzeit IT Team Manager - Global Field Sales Applications Elsbethen, Österreich Apply now To support our ambitious sales roadmap, we are looking for an IT Manager Global Field Sales Applications, who will drive the global IT field sales tool strategy with a bold, future‑focused agenda. In this role you'll sit in IT and at the frontline of Sales, turning ambitious commercial goals into a powerful, AI‑enabled applicat… | R10: Proje yönetimi, Ekip liderliği, Politika / uyum, Perakende / çok lokasyon | S10: Scripting / otomasyon (PowerShell vb.), ANA ŞART: İş uygulaması alanı (CRM/ERP/Legal/ServiceNow…), ANA ŞART: AI / ML | T10: 3 | U10: 5 | V10: 5 | W10: 5 | X10: 5 | Y10: 3.5 | Z10: =ROUND((T10*Özet!$C$14+U10*Özet!$C$15+V10*Özet!$C$16+W10*Özet!$C$17+X10*Özet!$C$18+Y10*Özet!$C$19)/5,4) -> 0.85 | AA10: =RANK(AE10,$AE$5:$AE$126)+COUNTIF($AE$5:AE10,AE10)-1 -> 6 | AB10: =IF(AND(OR(G10="EN",G10="EN (+DE artı)"),Z10>=0.7),"A – Hemen başvur (İngilizce)",IF(Z10>=0.7,"B – Başvur (Almanca gerekli)",IF(AND(OR(G10="EN",G10="EN (+DE artı)"),Z10>=0.6),"B – Başvur (İngilizce)","C – Opsiyonel"))) -> A – Hemen başvur (İngilizce) | AC10: İngilizce CV + ön yazı ile başvur | AD10: https://www.karriere.at/f/red-bull | AE10: =Z10+IF(OR(G10="EN",G10="EN (+DE artı)"),1,0) -> 1.85
A11: 7 | B11: TransUnion | C11: Technical Project Manager | D11: Salzburg, Salzburg, Austria | E11: ≤30 dk (Salzburg / yakın çevre) | F11: IT proje yönetimi | G11: EN | H11: Almanca şartı belirtilmemiş | I11: — | J11: Kıdemli / yönetici | K11: İlanda belirtilmemiş | L11: 2026-09-25 | M11: LinkedIn | N11: https://www.linkedin.com/jobs/view/4470334048 | O11: 27.09.2026 14:14 · HTTP 200 · AÇIK | Q11: TransUnion's Job Applicant Privacy Notice Team Overview Our team designs and develops solutions that strengthen secure, reliable communication across telecommunication networks. Our platforms are integrated into the ecosystem and technical infrastructure of mobile operators across Europe where our services process and analyze voice calls and messages to improve security and customer engagement for millions of end con… | R11: Ağ / Firewall / VPN, Proje yönetimi | S11: Programlama, ANA ŞART: AWS / GCP | T11: 3 | U11: 5 | V11: 5 | W11: 4 | X11: 5 | Y11: 3.5 | Z11: =ROUND((T11*Özet!$C$14+U11*Özet!$C$15+V11*Özet!$C$16+W11*Özet!$C$17+X11*Özet!$C$18+Y11*Özet!$C$19)/5,4) -> 0.84 | AA11: =RANK(AE11,$AE$5:$AE$126)+COUNTIF($AE$5:AE11,AE11)-1 -> 7 | AB11: =IF(AND(OR(G11="EN",G11="EN (+DE artı)"),Z11>=0.7),"A – Hemen başvur (İngilizce)",IF(Z11>=0.7,"B – Başvur (Almanca gerekli)",IF(AND(OR(G11="EN",G11="EN (+DE artı)"),Z11>=0.6),"B – Başvur (İngilizce)","C – Opsiyonel"))) -> A – Hemen başvur (İngilizce) | AC11: İngilizce CV + ön yazı ile başvur | AD11: https://www.linkedin.com/company/transunion | AE11: =Z11+IF(OR(G11="EN",G11="EN (+DE artı)"),1,0) -> 1.84
A12: 8 | B12: Red Bull | C12: IT Project / Application Manager - Production Application | D12: Elsbethen | E12: ≤30 dk (Salzburg / yakın çevre) | F12: IT proje yönetimi | G12: EN (+DE artı) | H12: English skills, German is a plus Sound knowledge of business processes in the field of produ | I12: — | J12: Kıdemli / yönetici | K12: Sadece KV asgarisi: ~€35k/yıl (ab 2.471 € monatlich) – gerçek maaş belirtilmemiş, genelde üstünde | L12: 2026-09-25 | M12: Red Bull resmi | N12: https://jobs.redbull.com/at-de/elsbethen-it-project-application-manager-production-application--ref26935q | O12: 27.09.2026 14:13 · HTTP 200 · AÇIK | P12: https://www.karriere.at/jobs/7709477 https://www.linkedin.com/jobs/view/4342957903 | Q12: Vollzeit IT Project / Application Manager - Production Application Elsbethen, Österreich Apply now Are you ready to make an impact where innovation meets operations? If you thrive in fast-paced environments, if you have a passion for optimizing systems, and you are ready to take ownership of transformative initiatives, we want you on our team to help us set new standards in SAP excellence! As an IT Project / Applicat… | R12: Proje yönetimi, Tedarikçi yönetimi, Bütçe | S12: ANA ŞART: SAP, ANA ŞART: İş uygulaması alanı (CRM/ERP/Legal/ServiceNow…) | T12: 2.5 | U12: 5 | V12: 5 | W12: 5 | X12: 5 | Y12: 3.5 | Z12: =ROUND((T12*Özet!$C$14+U12*Özet!$C$15+V12*Özet!$C$16+W12*Özet!$C$17+X12*Özet!$C$18+Y12*Özet!$C$19)/5,4) -> 0.82 | AA12: =RANK(AE12,$AE$5:$AE$126)+COUNTIF($AE$5:AE12,AE12)-1 -> 8 | AB12: =IF(AND(OR(G12="EN",G12="EN (+DE artı)"),Z12>=0.7),"A – Hemen başvur (İngilizce)",IF(Z12>=0.7,"B – Başvur (Almanca gerekli)",IF(AND(OR(G12="EN",G12="EN (+DE artı)"),Z12>=0.6),"B – Başvur (İngilizce)","C – Opsiyonel"))) -> A – Hemen başvur (İngilizce) | AC12: İngilizce CV + ön yazı ile başvur | AD12: https://www.karriere.at/f/red-bull | AE12: =Z12+IF(OR(G12="EN",G12="EN (+DE artı)"),1,0) -> 1.82
A13: 9 | B13: Amer Sports | C13: OT-Security Domain Manager(m/f/d) | D13: Altenmarkt im Pongau, Salzburg, Austria | E13: 60–90 dk | F13: Cyber Security – yönetişim / ISMS | G13: EN | H13: Almanca şartı belirtilmemiş | I13: — | J13: Kıdemli / yönetici | K13: İlanda belirtilmemiş | L13: 2026-09-27 | M13: LinkedIn | N13: https://www.linkedin.com/jobs/view/4438189985 | O13: 27.09.2026 14:14 · HTTP 200 · AÇIK | Q13: Hybrid / Altenmarkt im Pongau, Austria We’re looking for OT Security Domain Manager for Amer Sports ’ office in Altenmarkt im Pongau At Amer Sports, we are looking for an OT Security Domain Manager to lead and drive Operational Technology (OT) security across our global supply chain network. In this strategic role you will help safeguard manufacturing sites and distribution centers by embedding security into operatio… | R13: ISO 27001 / ISMS, ITIL / ITSM, Ağ / Firewall / VPN, Tedarikçi yönetimi, Ekip liderliği, Risk yönetimi, Politika / uyum, Denetim / audit | S13: Scripting / otomasyon (PowerShell vb.), SIEM / SOC / EDR, NIS-2 / DORA / TISAX, CISSP / CISM / CISA, ANA ŞART: OT / SCADA güvenliği | T13: 3.5 | U13: 5 | V13: 5 | W13: 4 | X13: 2 | Y13: 3.5 | Z13: =ROUND((T13*Özet!$C$14+U13*Özet!$C$15+V13*Özet!$C$16+W13*Özet!$C$17+X13*Özet!$C$18+Y13*Özet!$C$19)/5,4) -> 0.81 | AA13: =RANK(AE13,$AE$5:$AE$126)+COUNTIF($AE$5:AE13,AE13)-1 -> 9 | AB13: =IF(AND(OR(G13="EN",G13="EN (+DE artı)"),Z13>=0.7),"A – Hemen başvur (İngilizce)",IF(Z13>=0.7,"B – Başvur (Almanca gerekli)",IF(AND(OR(G13="EN",G13="EN (+DE artı)"),Z13>=0.6),"B – Başvur (İngilizce)","C – Opsiyonel"))) -> A – Hemen başvur (İngilizce) | AC13: İngilizce CV + ön yazı ile başvur · İletişim: talentacquisition@amersports.com | AD13: https://fi.linkedin.com/company/amer-sports | AE13: =Z13+IF(OR(G13="EN",G13="EN (+DE artı)"),1,0) -> 1.81
A14: 10 | B14: epunkt GmbH | C14: IT Allrounder (w/m/x) | D14: Bezirk Vöcklabruck | E14: 60–90 dk | F14: IT destek / service desk | G14: EN (+DE artı) | H14: gutes Englisch (Unternehmenssprache),Deutsch ist ein Plus, aber nicht zwingend erforderlich | I14: — | J14: Orta / giriş – aday overqualified | K14: ~€50k+/yıl (ilan: 3.600 € – 4.400 € monatlich) | L14: 2026-09-24 | M14: karriere.at | N14: https://www.karriere.at/jobs/7869100 | O14: 27.09.2026 14:14 · HTTP 200 · AÇIK | P14: https://www.karriere.at/jobs/7881199 | Q14: & Erfahrung zwischen 3.600 EUR und 4.400 EUR brutto / Monat (auf Vollzeitbasis). Brutto Netto Rechner Das Unternehmen Ein international tätiges Technologieunternehmen entwickelt ein patentiertes, wissenschaftlich validiertes Fit-System und arbeitet mit führenden Marken zusammen, um Sport- und Performance-Equipment durch präzise Passform und bessere Kraftübertragung zu optimieren. Das Unternehmen ist global aufgestell… | R14: ITIL / ITSM, Windows Server, Sanallaştırma (Hyper-V/Proxmox), Backup / DR, Ağ / Firewall / VPN, Ekip liderliği, Politika / uyum, Perakende / çok lokasyon | S14: Belirgin teknik eksik yok | T14: 4.5 | U14: 3 | V14: 5 | W14: 3.5 | X14: 2 | Y14: 3.5 | Z14: =ROUND((T14*Özet!$C$14+U14*Özet!$C$15+V14*Özet!$C$16+W14*Özet!$C$17+X14*Özet!$C$18+Y14*Özet!$C$19)/5,4) -> 0.805 | AA14: =RANK(AE14,$AE$5:$AE$126)+COUNTIF($AE$5:AE14,AE14)-1 -> 10 | AB14: =IF(AND(OR(G14="EN",G14="EN (+DE artı)"),Z14>=0.7),"A – Hemen başvur (İngilizce)",IF(Z14>=0.7,"B – Başvur (Almanca gerekli)",IF(AND(OR(G14="EN",G14="EN (+DE artı)"),Z14>=0.6),"B – Başvur (İngilizce)","C – Opsiyonel"))) -> A – Hemen başvur (İngilizce) | AC14: İngilizce CV + ön yazı ile başvur · Personel danışmanı ilanı → danışmanı telefon/e-posta ile ara, diğer açık pozisyonlarını da sor | AD14: https://www.karriere.at/f/epunkt-linz | AE14: =Z14+IF(OR(G14="EN",G14="EN (+DE artı)"),1,0) -> 1.805
A15: 11 | B15: TransUnion | C15: Senior Systems Administrator | D15: Salzburg, Salzburg, Austria | E15: ≤30 dk (Salzburg / yakın çevre) | F15: Sistem / altyapı | G15: EN | H15: Almanca şartı belirtilmemiş | I15: — | J15: Kıdemli / yönetici | K15: İlanda belirtilmemiş | L15: 2026-09-16 | M15: LinkedIn | N15: https://www.linkedin.com/jobs/view/4430598895 | O15: 27.09.2026 14:14 · HTTP 200 · AÇIK | Q15: TransUnion's Job Applicant Privacy Notice Team Overview Our team designs and develops solutions that strengthen secure, reliable communication across telecommunication networks. Our platforms are integrated into the ecosystem and technical infrastructure of mobile operators across Europe where our services process and analyze voice calls and messages to improve security and customer engagement for millions of end con… | R15: ITIL / ITSM, Sanallaştırma (Hyper-V/Proxmox), Backup / DR, Ağ / Firewall / VPN, SQL Server / DB, Proje yönetimi, Politika / uyum | S15: ANA ŞART: Scripting / otomasyon (PowerShell vb.), ANA ŞART: Linux, Container / IaC / DevOps, AWS / GCP | T15: 2.5 | U15: 4.5 | V15: 5 | W15: 4 | X15: 5 | Y15: 3.5 | Z15: =ROUND((T15*Özet!$C$14+U15*Özet!$C$15+V15*Özet!$C$16+W15*Özet!$C$17+X15*Özet!$C$18+Y15*Özet!$C$19)/5,4) -> 0.795 | AA15: =RANK(AE15,$AE$5:$AE$126)+COUNTIF($AE$5:AE15,AE15)-1 -> 11 | AB15: =IF(AND(OR(G15="EN",G15="EN (+DE artı)"),Z15>=0.7),"A – Hemen başvur (İngilizce)",IF(Z15>=0.7,"B – Başvur (Almanca gerekli)",IF(AND(OR(G15="EN",G15="EN (+DE artı)"),Z15>=0.6),"B – Başvur (İngilizce)","C – Opsiyonel"))) -> A – Hemen başvur (İngilizce) | AC15: İngilizce CV + ön yazı ile başvur | AD15: https://www.linkedin.com/company/transunion | AE15: =Z15+IF(OR(G15="EN",G15="EN (+DE artı)"),1,0) -> 1.795
A16: 12 | B16: Red Bull | C16: IT Infrastructure Engineer | D16: Thalgau | E16: 30–45 dk | F16: Sistem / altyapı | G16: EN (+DE artı) | H16: oder gleichwertige Berufserfahrung Fließende Englischkenntnisse, Deutschkenntnisse sind von Vorteil Mindestens fünf Jahre Berufserfahrung in d | I16: — | J16: Uzman (mid-senior) | K16: Sadece KV asgarisi: ~€35k/yıl (ab 2.535 € monatlich) – gerçek maaş belirtilmemiş, genelde üstünde | L16: 2026-09-25 | M16: Red Bull resmi | N16: https://jobs.redbull.com/at-de/it-infrastructure-data-platform-engineer-ref33287a | O16: 27.09.2026 14:13 · HTTP 200 · AÇIK | P16: https://www.karriere.at/jobs/7861804 https://www.linkedin.com/jobs/view/4455736906 https://www.linkedin.com/jobs/view/4455733965 | Q16: Vollzeit IT Infrastructure Engineer Thalgau, Österreich Bewerben Bist du bereit, Technologien mitzugestalten, die Höchstleistungen im Sport ermöglichen? Als IT Infrastructure Engineer spielst du eine zentrale Rolle innerhalb der Corporate Projects IT und unterstützt das Athlete Performance Center (APC) sowie dessen Plattformen, Anwendungen, Infrastruktur und spezialisierte Sporttechnologien. Mit deiner Arbeit schaffs… | R16: ITIL / ITSM, Ağ / Firewall / VPN, Tedarikçi yönetimi, Politika / uyum, Microsoft ortamı | S16: Azure / Entra ID, ANA ŞART: Scripting / otomasyon (PowerShell vb.), Programlama, AWS / GCP | T16: 3 | U16: 4 | V16: 5 | W16: 5 | X16: 4 | Y16: 3 | Z16: =ROUND((T16*Özet!$C$14+U16*Özet!$C$15+V16*Özet!$C$16+W16*Özet!$C$17+X16*Özet!$C$18+Y16*Özet!$C$19)/5,4) -> 0.79 | AA16: =RANK(AE16,$AE$5:$AE$126)+COUNTIF($AE$5:AE16,AE16)-1 -> 12 | AB16: =IF(AND(OR(G16="EN",G16="EN (+DE artı)"),Z16>=0.7),"A – Hemen başvur (İngilizce)",IF(Z16>=0.7,"B – Başvur (Almanca gerekli)",IF(AND(OR(G16="EN",G16="EN (+DE artı)"),Z16>=0.6),"B – Başvur (İngilizce)","C – Opsiyonel"))) -> A – Hemen başvur (İngilizce) | AC16: İngilizce CV + ön yazı ile başvur | AD16: https://www.karriere.at/f/red-bull | AE16: =Z16+IF(OR(G16="EN",G16="EN (+DE artı)"),1,0) -> 1.79
A17: 13 | B17: Red Bull | C17: IT Project Manager - Sales Applications | D17: Elsbethen | E17: ≤30 dk (Salzburg / yakın çevre) | F17: IT proje yönetimi | G17: EN (+DE artı) | H17: or equivalent practical experience Fluent English skills, German is a plus At least 4 years of experience in the IT environment with a | I17: — | J17: Kıdemli / yönetici | K17: Sadece KV asgarisi: ~€33k/yıl (ab 2.362 € monatlich) – gerçek maaş belirtilmemiş, genelde üstünde | L17: 2026-09-20 | M17: Red Bull resmi | N17: https://jobs.redbull.com/at-de/elsbethen-it-project-manager-sales-applications--ref31123e | O17: 27.09.2026 14:14 · HTTP 200 · AÇIK | P17: https://www.karriere.at/jobs/7871212 | Q17: Vollzeit IT Project Manager - Sales Applications Elsbethen, Österreich Apply now To support our ambitious sales roadmap with exciting IT sales projects and new initiatives, we are expanding our Global IT Sales Projects team and are looking for a driven IT Project Manager in the area of sales applications. In this role, you will equip our global sales teams with the tools and "wings" they need to sell smarter, faster,… | R17: Proje yönetimi, Tedarikçi yönetimi, Bütçe, Risk yönetimi | S17: Azure / Entra ID, Scripting / otomasyon (PowerShell vb.), SAP, AWS / GCP, ANA ŞART: İş uygulaması alanı (CRM/ERP/Legal/ServiceNow…), ANA ŞART: AI / ML | T17: 1.5 | U17: 5 | V17: 5 | W17: 5 | X17: 5 | Y17: 3.5 | Z17: =ROUND((T17*Özet!$C$14+U17*Özet!$C$15+V17*Özet!$C$16+W17*Özet!$C$17+X17*Özet!$C$18+Y17*Özet!$C$19)/5,4) -> 0.76 | AA17: =RANK(AE17,$AE$5:$AE$126)+COUNTIF($AE$5:AE17,AE17)-1 -> 13 | AB17: =IF(AND(OR(G17="EN",G17="EN (+DE artı)"),Z17>=0.7),"A – Hemen başvur (İngilizce)",IF(Z17>=0.7,"B – Başvur (Almanca gerekli)",IF(AND(OR(G17="EN",G17="EN (+DE artı)"),Z17>=0.6),"B – Başvur (İngilizce)","C – Opsiyonel"))) -> A – Hemen başvur (İngilizce) | AC17: İngilizce CV + ön yazı ile başvur | AD17: https://www.karriere.at/f/red-bull | AE17: =Z17+IF(OR(G17="EN",G17="EN (+DE artı)"),1,0) -> 1.76
A18: 14 | B18: PALFINGER | C18: Cyber Security Engineer (f/m/d) | D18: Bergheim, Salzburg, Austria | E18: ≤30 dk (Salzburg / yakın çevre) | F18: Cyber Security – teknik | G18: EN | H18: Almanca şartı belirtilmemiş | I18: — | J18: Uzman (mid-senior) | K18: ~€53k+/yıl (ilan metninden) | L18: 2026-09-01 | M18: LinkedIn | N18: https://www.linkedin.com/jobs/view/4461705351 | O18: 27.09.2026 14:14 · HTTP 200 · AÇIK | Q18: At PALFINGER, we have been lifting goods to a new level for over 90 years - with a pioneering and passionate spirit. As a global technology and engineering company, we are the world's leading manufacturer and supplier of innovative crane and lifting solutions. Our success is based on the tireless efforts of our approximately 12,350 employees, who contribute their ideas and energy to our vision. With us, you can expec… | R18: ITIL / ITSM, Active Directory, Ağ / Firewall / VPN, Tedarikçi yönetimi, Politika / uyum, Denetim / audit, Microsoft ortamı | S18: ANA ŞART: Azure / Entra ID, Intune / M365 admin, Scripting / otomasyon (PowerShell vb.), SIEM / SOC / EDR, Ağ üreticisi sertifikası (Cisco/Fortinet/Palo Alto), CISSP / CISM / CISA | T18: 2 | U18: 4 | V18: 5 | W18: 4 | X18: 5 | Y18: 4 | Z18: =ROUND((T18*Özet!$C$14+U18*Özet!$C$15+V18*Özet!$C$16+W18*Özet!$C$17+X18*Özet!$C$18+Y18*Özet!$C$19)/5,4) -> 0.76 | AA18: =RANK(AE18,$AE$5:$AE$126)+COUNTIF($AE$5:AE18,AE18)-1 -> 14 | AB18: =IF(AND(OR(G18="EN",G18="EN (+DE artı)"),Z18>=0.7),"A – Hemen başvur (İngilizce)",IF(Z18>=0.7,"B – Başvur (Almanca gerekli)",IF(AND(OR(G18="EN",G18="EN (+DE artı)"),Z18>=0.6),"B – Başvur (İngilizce)","C – Opsiyonel"))) -> A – Hemen başvur (İngilizce) | AC18: İngilizce CV + ön yazı ile başvur | AD18: https://at.linkedin.com/company/palfinger | AE18: =Z18+IF(OR(G18="EN",G18="EN (+DE artı)"),1,0) -> 1.76
A19: 15 | B19: Aptean | C19: ERP Customer Support Consultant | D19: Salzburg, Austria | E19: ≤30 dk (Salzburg / yakın çevre) | F19: IT destek / service desk | G19: EN | H19: Almanca şartı belirtilmemiş | I19: — | J19: Orta / giriş – aday overqualified | K19: Sadece KV asgarisi: ~€36k/yıl (ilan metni) – gerçek maaş belirtilmemiş, genelde üstünde | L19: 2026-09-22 | M19: LinkedIn | N19: https://www.linkedin.com/jobs/view/4459659551 | O19: 27.09.2026 14:14 · HTTP 200 · AÇIK | Q19: Customer Support Consultant (m/w/d) mit Fokus auf Rechnungswesen Bergheim bei Salzburg | Hybrid Was die Menschen bei Aptean eint, ist ihr Engagement, Kundenprozesse zu vereinfachen und Erwartungen zu übertreffen. Unsere gemeinsame Vision ist die Entwicklung modernster ERP-Softwarelösungen für Mittel- und Großbetriebe. Wir wachsen überdurchschnittlich und suchen DICH zur Verstärkung unseres Customer Service Teams. Du… | R19: SQL Server / DB, Tedarikçi yönetimi, Politika / uyum | S19: Programlama, ANA ŞART: İş uygulaması alanı (CRM/ERP/Legal/ServiceNow…), ANA ŞART: AI / ML | T19: 2.5 | U19: 3 | V19: 5 | W19: 4 | X19: 5 | Y19: 3 | Z19: =ROUND((T19*Özet!$C$14+U19*Özet!$C$15+V19*Özet!$C$16+W19*Özet!$C$17+X19*Özet!$C$18+Y19*Özet!$C$19)/5,4) -> 0.74 | AA19: =RANK(AE19,$AE$5:$AE$126)+COUNTIF($AE$5:AE19,AE19)-1 -> 15 | AB19: =IF(AND(OR(G19="EN",G19="EN (+DE artı)"),Z19>=0.7),"A – Hemen başvur (İngilizce)",IF(Z19>=0.7,"B – Başvur (Almanca gerekli)",IF(AND(OR(G19="EN",G19="EN (+DE artı)"),Z19>=0.6),"B – Başvur (İngilizce)","C – Opsiyonel"))) -> A – Hemen başvur (İngilizce) | AC19: İngilizce CV + ön yazı ile başvur | AD19: https://www.linkedin.com/company/aptean | AE19: =Z19+IF(OR(G19="EN",G19="EN (+DE artı)"),1,0) -> 1.74
A20: 16 | B20: SKIDATA | C20: Product Security Engineer (mfd) | D20: Wals-Siezenheim, Salzburg, Austria | E20: ≤30 dk (Salzburg / yakın çevre) | F20: Cyber Security – teknik | G20: EN | H20: Almanca şartı belirtilmemiş | I20: — | J20: Uzman (mid-senior) | K20: İlanda belirtilmemiş | L20: 2026-09-19 | M20: LinkedIn | N20: https://www.linkedin.com/jobs/view/4440762411 | O20: 27.09.2026 14:14 · HTTP 200 · AÇIK | Q20: Strong experience with secure coding practices and code analysis tools Solid threat modeling expertise and hands-on penetration testing experience Sound knowledge of OWASP principles and IT security standards (ISO 27001, NIST Cybersecurity, PCI DSS, or similar) Familiarity with DevOps practices and tools Proficiency in programming languages such as Java, C#, or .NET Experience with cloud services, Docker, and microse… | R20: ISO 27001 / ISMS | S20: Container / IaC / DevOps, ANA ŞART: Programlama, Pentest, ANA ŞART: Application security / secure SDLC | T20: 1.5 | U20: 4 | V20: 5 | W20: 4 | X20: 5 | Y20: 3 | Z20: =ROUND((T20*Özet!$C$14+U20*Özet!$C$15+V20*Özet!$C$16+W20*Özet!$C$17+X20*Özet!$C$18+Y20*Özet!$C$19)/5,4) -> 0.71 | AA20: =RANK(AE20,$AE$5:$AE$126)+COUNTIF($AE$5:AE20,AE20)-1 -> 16 | AB20: =IF(AND(OR(G20="EN",G20="EN (+DE artı)"),Z20>=0.7),"A – Hemen başvur (İngilizce)",IF(Z20>=0.7,"B – Başvur (Almanca gerekli)",IF(AND(OR(G20="EN",G20="EN (+DE artı)"),Z20>=0.6),"B – Başvur (İngilizce)","C – Opsiyonel"))) -> A – Hemen başvur (İngilizce) | AC20: İngilizce CV + ön yazı ile başvur | AD20: https://at.linkedin.com/company/skidata-ag | AE20: =Z20+IF(OR(G20="EN",G20="EN (+DE artı)"),1,0) -> 1.71
A21: 17 | B21: Rehrl+Partner Personalberatung GmbH | C21: Leitung IT-Infrastruktur (m/w/d) | D21: Salzburg, Salzburg, Austria | E21: ≤30 dk (Salzburg / yakın çevre) | F21: IT yönetimi / liderlik | G21: DE | H21: İlan Almanca; seviye belirtilmemiş | I21: — | J21: Kıdemli / yönetici | K21: ~€100k+/yıl (ilan metninden) | L21: 2026-09-21 | M21: LinkedIn | N21: https://www.linkedin.com/jobs/view/4462230078 | O21: 27.09.2026 14:14 · HTTP 200 · AÇIK | Q21: Abgeschlossene Ausbildung im Bereich IT, IT-Management oder Informatik Mehrjährige Berufserfahrung in der IT-Infrastruktur sowie umfangreiche Führungserfahrung Idealerweise Erfahrung in der produzierenden Industrie mit internationalen Standorten Fundierte Kenntnisse in der Koordination komplexer operativer IT-Einheiten sowie Dienstleister Sicherer Umgang mit Budget- und Vertragsangelegenheiten, hohes Kennzahlenbewuss… | R21: Ağ / Firewall / VPN, Tedarikçi yönetimi, Bütçe, Ekip liderliği, Perakende / çok lokasyon | S21: Belirgin teknik eksik yok | T21: 5 | U21: 5 | V21: 1.5 | W21: 3.5 | X21: 5 | Y21: 5 | Z21: =ROUND((T21*Özet!$C$14+U21*Özet!$C$15+V21*Özet!$C$16+W21*Özet!$C$17+X21*Özet!$C$18+Y21*Özet!$C$19)/5,4) -> 0.775 | AA21: =RANK(AE21,$AE$5:$AE$126)+COUNTIF($AE$5:AE21,AE21)-1 -> 17 | AB21: =IF(AND(OR(G21="EN",G21="EN (+DE artı)"),Z21>=0.7),"A – Hemen başvur (İngilizce)",IF(Z21>=0.7,"B – Başvur (Almanca gerekli)",IF(AND(OR(G21="EN",G21="EN (+DE artı)"),Z21>=0.6),"B – Başvur (İngilizce)","C – Opsiyonel"))) -> B – Başvur (Almanca gerekli) | AC21: Almanca CV + Anschreiben ile başvur (Almanca B1/B2 belirt) · Personel danışmanı ilanı → danışmanı telefon/e-posta ile ara, diğer açık pozisyonlarını da sor | AD21: https://at.linkedin.com/company/rehrl-partner-personalberatung-gmbh | AE21: =Z21+IF(OR(G21="EN",G21="EN (+DE artı)"),1,0) -> 0.775
A22: 18 | B22: KERN engineering careers GmbH | C22: Information Security Consultant (w/m/d) | D22: Graz, Klagenfurt, Salzburg, Wels, Wien | E22: ≤30 dk (Salzburg / yakın çevre) | F22: Cyber Security – yönetişim / ISMS | G22: DE+EN | H22: und die Fähigkeit, komplexe Sachverhalte verständlich in Deutsch & Englisch zu vermitteln Sicheres Auftreten im Kundenkontakt sowie Fr | I22: — | J22: Kıdemli / yönetici | K22: ~€70k+/yıl (ilan: 5.000 € – 6.000 € monatlich) | L22: 2026-09-25 | M22: karriere.at | N22: https://www.karriere.at/jobs/7829969 | O22: 27.09.2026 14:13 · HTTP 200 · AÇIK | Q22: wie ISO 2700x und NIS2 ; Zertifizierungen von Vorteil Ausgeprägte Kommunikationsstärke und die Fähigkeit, komplexe Sachverhalte verständlich in Deutsch & Englisch zu vermitteln Sicheres Auftreten im Kundenkontakt sowie Freude an der Arbeit in einem beratenden Umfeld Worauf man sich freuen kann Eine verantwortungsvolle Position mit großem Gestaltungsspielraum in einem wachsenden Marktsegment Flexible Arbeitszeiten sow… | R22: ITIL / ITSM, Ekip liderliği, Denetim / audit | S22: NIS-2 / DORA / TISAX | T22: 4.5 | U22: 5 | V22: 2 | W22: 3.5 | X22: 5 | Y22: 5 | Z22: =ROUND((T22*Özet!$C$14+U22*Özet!$C$15+V22*Özet!$C$16+W22*Özet!$C$17+X22*Özet!$C$18+Y22*Özet!$C$19)/5,4) -> 0.775 | AA22: =RANK(AE22,$AE$5:$AE$126)+COUNTIF($AE$5:AE22,AE22)-1 -> 18 | AB22: =IF(AND(OR(G22="EN",G22="EN (+DE artı)"),Z22>=0.7),"A – Hemen başvur (İngilizce)",IF(Z22>=0.7,"B – Başvur (Almanca gerekli)",IF(AND(OR(G22="EN",G22="EN (+DE artı)"),Z22>=0.6),"B – Başvur (İngilizce)","C – Opsiyonel"))) -> B – Başvur (Almanca gerekli) | AC22: Almanca CV ile başvur; İngilizce yeterliliğini ve Almanca B1/B2'yi açıkça yaz · Personel danışmanı ilanı → danışmanı telefon/e-posta ile ara, diğer açık pozisyonlarını da sor · İletişim: j.wagner@kern-partner.at | AD22: https://www.karriere.at/f/kern-engineering-careers | AE22: =Z22+IF(OR(G22="EN",G22="EN (+DE artı)"),1,0) -> 0.775
A23: 19 | B23: Salzburger Abfallbeseitigung GmbH | C23: Koordinator für Informationssicherheit und Managementsysteme (m/w/d) | D23: Salzburg (Stadt) | E23: ≤30 dk (Salzburg / yakın çevre) | F23: Cyber Security – yönetişim / ISMS | G23: DE | H23: İlan Almanca; seviye belirtilmemiş | I23: — | J23: Kıdemli / yönetici | K23: ~€60k+/yıl (ilan: ab 4.320 € monatlich) | L23: 2026-09-22 | M23: karriere.at | N23: https://www.karriere.at/jobs/10033426 | O23: 27.09.2026 14:14 · HTTP 200 · AÇIK | Q23: Eine abgeschlossene Ausbildung mit IT-Schwerpunkt, etwa HTL, FH, Universität oder IT-Lehre mit entsprechender Berufserfahrung. Praktische Erfahrung mit IT-Systemen, Netzwerken und grundlegenden Sicherheitsmaßnahmen. Idealerweise eine abgeschlossene Zusatzausbildung im Qualitätsmanagement, in der internen Auditierung oder in integrierten Managementsystemen (z. B. TÜV AUSTRIA, TÜV SÜD oder einem vergleichbaren Anbieter… | R23: Backup / DR, Ağ / Firewall / VPN, Tedarikçi yönetimi, Ekip liderliği, Risk yönetimi, Politika / uyum, Denetim / audit, Perakende / çok lokasyon | S23: NIS-2 / DORA / TISAX | T23: 5 | U23: 5 | V23: 1.5 | W23: 4 | X23: 5 | Y23: 4.5 | Z23: =ROUND((T23*Özet!$C$14+U23*Özet!$C$15+V23*Özet!$C$16+W23*Özet!$C$17+X23*Özet!$C$18+Y23*Özet!$C$19)/5,4) -> 0.77 | AA23: =RANK(AE23,$AE$5:$AE$126)+COUNTIF($AE$5:AE23,AE23)-1 -> 19 | AB23: =IF(AND(OR(G23="EN",G23="EN (+DE artı)"),Z23>=0.7),"A – Hemen başvur (İngilizce)",IF(Z23>=0.7,"B – Başvur (Almanca gerekli)",IF(AND(OR(G23="EN",G23="EN (+DE artı)"),Z23>=0.6),"B – Başvur (İngilizce)","C – Opsiyonel"))) -> B – Başvur (Almanca gerekli) | AC23: Almanca CV + Anschreiben ile başvur (Almanca B1/B2 belirt) | AD23: https://www.karriere.at/f/salzburger-abfallbeseitigung | AE23: =Z23+IF(OR(G23="EN",G23="EN (+DE artı)"),1,0) -> 0.77
A24: 20 | B24: Xenium AG | C24: Lead IT Consultant Digitalisierung & Projektleitung (m/w/d) | D24: Salzburg, Austria | E24: ≤30 dk (Salzburg / yakın çevre) | F24: IT proje yönetimi | G24: DE+EN | H24: kommunizierst sicher auf Deutsch und Englisch und bist etwa 1–2 Tage pro Woche beim Kunden vor Ort Dei | I24: — | J24: Kıdemli / yönetici | K24: ~€83k+/yıl (ilan metninden) | L24: 2026-09-07 | M24: LinkedIn | N24: https://www.linkedin.com/jobs/view/4461881030 | O24: 27.09.2026 14:14 · HTTP 200 · AÇIK | Q24: Du hast ein Studium im MINT- oder wirtschaftsnahen Bereich mit IT-Bezug erfolgreich abgeschlossen Du bringst Erfahrung im IT-Consulting sowie in der Führung von Projekten oder Teams mit Du überzeugst durch Empathie, Souveränität und klare Kommunikation Du denkst analytisch, arbeitest konzeptionell und treibst Digitalisierungsthemen mit Begeisterung voran Du denkst analytisch­ und konzeptionell­ und bist klar und präz… | R24: Proje yönetimi, Ekip liderliği | S24: Belirgin teknik eksik yok | T24: 4 | U24: 5 | V24: 2 | W24: 4 | X24: 5 | Y24: 5 | Z24: =ROUND((T24*Özet!$C$14+U24*Özet!$C$15+V24*Özet!$C$16+W24*Özet!$C$17+X24*Özet!$C$18+Y24*Özet!$C$19)/5,4) -> 0.75 | AA24: =RANK(AE24,$AE$5:$AE$126)+COUNTIF($AE$5:AE24,AE24)-1 -> 20 | AB24: =IF(AND(OR(G24="EN",G24="EN (+DE artı)"),Z24>=0.7),"A – Hemen başvur (İngilizce)",IF(Z24>=0.7,"B – Başvur (Almanca gerekli)",IF(AND(OR(G24="EN",G24="EN (+DE artı)"),Z24>=0.6),"B – Başvur (İngilizce)","C – Opsiyonel"))) -> B – Başvur (Almanca gerekli) | AC24: Almanca CV ile başvur; İngilizce yeterliliğini ve Almanca B1/B2'yi açıkça yaz | AD24: https://de.linkedin.com/company/xenium-ag | AE24: =Z24+IF(OR(G24="EN",G24="EN (+DE artı)"),1,0) -> 0.75
A25: 21 | B25: x-tention Informationstechnologie GmbH | C25: Senior Cyber Security Consultant & Project Manager (m/w/d) | D25: Klagenfurt am Wörthersee, Wien, St. Peter in der Au, Graz, Wels, Salzburg (Stadt) | E25: ≤30 dk (Salzburg / yakın çevre) | F25: Cyber Security – yönetişim / ISMS | G25: DE+EN | H25: & private Vergaben) von Vorteil Stark in Präsentation & Moderation (Deutsch und Englisch) Zertifizierungen wie CISSP, CISM, ITIL sowie Projektman | I25: — | J25: Kıdemli / yönetici | K25: ~€65k+/yıl (ilan: 4.610 € – 5.715 € monatlich) | L25: 2026-09-22 | M25: karriere.at | N25: https://www.karriere.at/jobs/10033472 | O25: 27.09.2026 14:13 · HTTP 200 · AÇIK | Q25: Mehrjährige Erfahrung im Cybersecurity-Consulting und/oder Projektmanagement Fundiertes Know-how im SIEM/SOC-Umfeld, Use-Cases, Runbooks & KPI/SLAs Erfahrung in Ausschreibungsbearbeitung (öffentliche & private Vergaben) von Vorteil Stark in Präsentation & Moderation (Deutsch und Englisch) Zertifizierungen wie CISSP, CISM, ITIL sowie Projektmanagement-Standards wie IPMA oder PRINCE2/PMP von Vorteil Strukturierte, lösu… | R25: ITIL / ITSM, Proje yönetimi, Bütçe, Ekip liderliği, Risk yönetimi, Perakende / çok lokasyon | S25: ANA ŞART: SIEM / SOC / EDR, CISSP / CISM / CISA | T25: 4 | U25: 5 | V25: 2 | W25: 4 | X25: 5 | Y25: 4.5 | Z25: =ROUND((T25*Özet!$C$14+U25*Özet!$C$15+V25*Özet!$C$16+W25*Özet!$C$17+X25*Özet!$C$18+Y25*Özet!$C$19)/5,4) -> 0.74 | AA25: =RANK(AE25,$AE$5:$AE$126)+COUNTIF($AE$5:AE25,AE25)-1 -> 21 | AB25: =IF(AND(OR(G25="EN",G25="EN (+DE artı)"),Z25>=0.7),"A – Hemen başvur (İngilizce)",IF(Z25>=0.7,"B – Başvur (Almanca gerekli)",IF(AND(OR(G25="EN",G25="EN (+DE artı)"),Z25>=0.6),"B – Başvur (İngilizce)","C – Opsiyonel"))) -> B – Başvur (Almanca gerekli) | AC25: Almanca CV ile başvur; İngilizce yeterliliğini ve Almanca B1/B2'yi açıkça yaz | AD25: https://www.karriere.at/f/x-tention-informationstechnologie | AE25: =Z25+IF(OR(G25="EN",G25="EN (+DE artı)"),1,0) -> 0.74
A26: 22 | B26: Soulkitchen Group | C26: IT-Manager (m/w/d) | D26: Salzburg, Salzburg, Austria | E26: ≤30 dk (Salzburg / yakın çevre) | F26: IT yönetimi / liderlik | G26: DE C1 | H26: an unseren Standorten in Österreich und Deutschland Sehr gute Deutsch- und Englischkenntnisse Führerschein Klasse B WIR GARANTIEREN DIR Ein | I26: — | J26: Kıdemli / yönetici | K26: ~€56k+/yıl (ilan metninden) | L26: 2026-09-24 | M26: LinkedIn | N26: https://www.linkedin.com/jobs/view/4469750644 | O26: 27.09.2026 14:14 · HTTP 200 · AÇIK | Q26: über die Umsetzung bis hin zum laufenden Betrieb. Bei Neu-, Um- und Ausbauprojekten begleitest du den gesamten IT-Prozess von der Planung bis zur Inbetriebnahme. Du konzipierst Netzwerk, WLAN, Verkabelung und Netzwerkschränke, definierst die benötigte IT- und Store-Ausstattung, koordinierst externe Partner und Gewerke und stellst eine professionelle technische Abnahme sowie eine reibungslose Übergabe in den laufenden… | R26: Ağ / Firewall / VPN, Tedarikçi yönetimi, Ekip liderliği, Microsoft ortamı, Perakende / çok lokasyon | S26: Almanca C1 / çok iyi Almanca | T26: 5 | U26: 5 | V26: 1 | W26: 5 | X26: 5 | Y26: 4 | Z26: =ROUND((T26*Özet!$C$14+U26*Özet!$C$15+V26*Özet!$C$16+W26*Özet!$C$17+X26*Özet!$C$18+Y26*Özet!$C$19)/5,4) -> 0.74 | AA26: =RANK(AE26,$AE$5:$AE$126)+COUNTIF($AE$5:AE26,AE26)-1 -> 22 | AB26: =IF(AND(OR(G26="EN",G26="EN (+DE artı)"),Z26>=0.7),"A – Hemen başvur (İngilizce)",IF(Z26>=0.7,"B – Başvur (Almanca gerekli)",IF(AND(OR(G26="EN",G26="EN (+DE artı)"),Z26>=0.6),"B – Başvur (İngilizce)","C – Opsiyonel"))) -> B – Başvur (Almanca gerekli) | AC26: Almanca C1 isteniyor – yine de başvurmak istersen Almanca CV + dil planı (kurs/sertifika) belirt · İletişim: bewerbung@soulkitchen.world | AD26: https://at.linkedin.com/company/soulkitchen-group | AE26: =Z26+IF(OR(G26="EN",G26="EN (+DE artı)"),1,0) -> 0.74
A27: 23 | B27: HR Consulting Ines Schöffmann GmbH | C27: IT-Sicherheitsarchitekt:in | D27: Zell Am See, Salzburg, Austria | E27: 60–90 dk | F27: Cyber Security – yönetişim / ISMS | G27: DE+EN | H27: Breites Wissen im Bereich IT Security Projektleitungserfahrung Deutsch und Englisch Das Angebot Eine sichere Festanstellung in einem wirtsch | I27: — | J27: Kıdemli / yönetici | K27: ~€65k+/yıl (ilan metninden) | L27: 2026-09-23 | M27: LinkedIn | N27: https://www.linkedin.com/jobs/view/4470695814 | O27: 27.09.2026 14:14 · HTTP 200 · AÇIK | Q27: und triffst Technologientscheidungen planst und leitest Projekte Dazu kommen Dienstleister- und Schnittstellenmanagement, Dokumentation, Projektmitarbeit, etc. Dein Background Fundierter IT Hintergrund (HTL, Studium und/oder einschlägige Erfahrung) Breites Wissen im Bereich IT Security Projektleitungserfahrung Deutsch und Englisch Das Angebot Eine sichere Festanstellung in einem wirtschaftlich gesunden, eigentümergef… | R27: Proje yönetimi, Tedarikçi yönetimi, Risk yönetimi, Politika / uyum, Denetim / audit | S27: Pentest | T27: 5 | U27: 5 | V27: 2 | W27: 3.5 | X27: 2 | Y27: 4.5 | Z27: =ROUND((T27*Özet!$C$14+U27*Özet!$C$15+V27*Özet!$C$16+W27*Özet!$C$17+X27*Özet!$C$18+Y27*Özet!$C$19)/5,4) -> 0.735 | AA27: =RANK(AE27,$AE$5:$AE$126)+COUNTIF($AE$5:AE27,AE27)-1 -> 23 | AB27: =IF(AND(OR(G27="EN",G27="EN (+DE artı)"),Z27>=0.7),"A – Hemen başvur (İngilizce)",IF(Z27>=0.7,"B – Başvur (Almanca gerekli)",IF(AND(OR(G27="EN",G27="EN (+DE artı)"),Z27>=0.6),"B – Başvur (İngilizce)","C – Opsiyonel"))) -> B – Başvur (Almanca gerekli) | AC27: Almanca CV ile başvur; İngilizce yeterliliğini ve Almanca B1/B2'yi açıkça yaz · Personel danışmanı ilanı → danışmanı telefon/e-posta ile ara, diğer açık pozisyonlarını da sor · İletişim: office@hr-schoeffmann.at | AD27: https://www.linkedin.com/company/hr-consulting-ines-sch%C3%B6ffmann-gmbh | AE27: =Z27+IF(OR(G27="EN",G27="EN (+DE artı)"),1,0) -> 0.735
A28: 24 | B28: SPAR ICS – Information & Communication Services | C28: Product Lead IT Network (m/w/d) | D28: Wien, Salzburg (Stadt) | E28: ≤30 dk (Salzburg / yakın çevre) | F28: IT yönetimi / liderlik | G28: DE C1 | H28: Freude an der Zusammenarbeit mit internationalen Teams Fließenden Deutsch- und Englischkenntnissen in Wort und Schrift Darauf kannst du dich fr | I28: — | J28: Kıdemli / yönetici | K28: ~€60k+/yıl (ilan: ab 60.000 € jährlich) | L28: 2026-09-22 | M28: karriere.at | N28: https://www.karriere.at/jobs/7880023 | O28: 27.09.2026 14:13 · HTTP 200 · AÇIK | P28: https://www.linkedin.com/jobs/view/4470455077 | Q28: Mehrjähriger Berufserfahrung im Bereich Netzwerkarchitektur und Netzwerksicherheit Expertenwissen in Design, Implementierung und Administration von WAN-Lösungen Fundierten Kenntnissen moderner WAN- und LAN-Technologien sowie relevanter Protokolle (BGP, MPLS, WDM, QoS, Cisco SD-WAN, 5G WAN) Erfahrung in der Steuerung von Netzwerk-Service-Providern von Vorteil Kommunikationsstärke und der Fähigkeit, komplexe technische… | R28: Ağ / Firewall / VPN, Tedarikçi yönetimi, Perakende / çok lokasyon | S28: Almanca C1 / çok iyi Almanca, Ağ üreticisi sertifikası (Cisco/Fortinet/Palo Alto) | T28: 4.5 | U28: 5 | V28: 1 | W28: 5 | X28: 5 | Y28: 4.5 | Z28: =ROUND((T28*Özet!$C$14+U28*Özet!$C$15+V28*Özet!$C$16+W28*Özet!$C$17+X28*Özet!$C$18+Y28*Özet!$C$19)/5,4) -> 0.72 | AA28: =RANK(AE28,$AE$5:$AE$126)+COUNTIF($AE$5:AE28,AE28)-1 -> 24 | AB28: =IF(AND(OR(G28="EN",G28="EN (+DE artı)"),Z28>=0.7),"A – Hemen başvur (İngilizce)",IF(Z28>=0.7,"B – Başvur (Almanca gerekli)",IF(AND(OR(G28="EN",G28="EN (+DE artı)"),Z28>=0.6),"B – Başvur (İngilizce)","C – Opsiyonel"))) -> B – Başvur (Almanca gerekli) | AC28: Almanca C1 isteniyor – yine de başvurmak istersen Almanca CV + dil planı (kurs/sertifika) belirt | AD28: https://www.karriere.at/f/spar-ics-information-communication-services | AE28: =Z28+IF(OR(G28="EN",G28="EN (+DE artı)"),1,0) -> 0.72
A29: 25 | B29: Deloitte | C29: (Senior) Manager ServiceNow Architekt (all genders) | D29: Salzburg, Salzburg, Austria | E29: ≤30 dk (Salzburg / yakın çevre) | F29: IT servis yönetimi (ITIL) | G29: DE+EN | H29: besitzt exzellente kommunikative Fähigkeiten in Deutsch und Englisch Erfüllst du nicht alle genannten Kriterien? Kein Problem | I29: — | J29: Kıdemli / yönetici | K29: ~€67k+/yıl (ilan metninden) | L29: 2026-09-23 | M29: LinkedIn | N29: https://www.linkedin.com/jobs/view/4292781889 | O29: 27.09.2026 14:14 · HTTP 200 · AÇIK | Q29: Du hast ein abgeschlossenes Studium der Informatik oder verwandter Fachbereiche, bevorzugt mit Spezialisierung auf IT-Infrastruktur, Softwareentwicklung oder Data Science. Du bringst mindestens 5 Jahre Erfahrung in ITSM und/oder der Implementierung von ServiceNow mit, einschließlich Erfahrung in leitenden Positionen. Du verfügst über vertiefte Kenntnisse in der Architektur von IT-Lösungen und im Projektmanagement. Du… | R29: ITIL / ITSM, SQL Server / DB, Proje yönetimi, Ekip liderliği, Perakende / çok lokasyon | S29: Scripting / otomasyon (PowerShell vb.), Programlama, ANA ŞART: İş uygulaması alanı (CRM/ERP/Legal/ServiceNow…) | T29: 3.5 | U29: 5 | V29: 2 | W29: 4 | X29: 5 | Y29: 4.5 | Z29: =ROUND((T29*Özet!$C$14+U29*Özet!$C$15+V29*Özet!$C$16+W29*Özet!$C$17+X29*Özet!$C$18+Y29*Özet!$C$19)/5,4) -> 0.71 | AA29: =RANK(AE29,$AE$5:$AE$126)+COUNTIF($AE$5:AE29,AE29)-1 -> 25 | AB29: =IF(AND(OR(G29="EN",G29="EN (+DE artı)"),Z29>=0.7),"A – Hemen başvur (İngilizce)",IF(Z29>=0.7,"B – Başvur (Almanca gerekli)",IF(AND(OR(G29="EN",G29="EN (+DE artı)"),Z29>=0.6),"B – Başvur (İngilizce)","C – Opsiyonel"))) -> B – Başvur (Almanca gerekli) | AC29: Almanca CV ile başvur; İngilizce yeterliliğini ve Almanca B1/B2'yi açıkça yaz · İletişim: barrierefreiheit@deloitte.at. | AD29: https://www.linkedin.com/company/deloitte | AE29: =Z29+IF(OR(G29="EN",G29="EN (+DE artı)"),1,0) -> 0.71
A30: 26 | B30: ReqPOOL GmbH | C30: Projektmanager Beratung mit PO-Erfahrung für Software & Digitalisierung (m/w/d) im Bereich Energy | D30: Linz, Wien, Salzburg (Stadt) | E30: ≤30 dk (Salzburg / yakın çevre) | F30: IT proje yönetimi | G30: DE C1 | H30: mit PO-Zertifizierung (CSPO, PSPO) Du bist reisebereit im deutschsprachigen Raum, ergänzend zur Büro- und Home-Office-Arbeit Du sprichs | I30: — | J30: Kıdemli / yönetici | K30: ~€66k+/yıl (ilan: 66.000 € – 76.000 € jährlich) | L30: 2026-09-20 | M30: karriere.at | N30: https://www.karriere.at/jobs/7859100 | O30: 27.09.2026 14:14 · HTTP 200 · AÇIK | Q30: kritisch, übersetzt sie in umsetzbare Spezifikationen und managst Erwartungen zu Scope, Zeit und Budget Du erstellst Fachkonzepte (Screens, Navigations-, Rollen- und Rechtekonzepte), Business Cases, Prozessmodelle sowie Markt- und Datenanalysen, Ausschreibungsunterlagen und Benchmarkings - inklusive fachlichem Verständnis für Systemanbindungen und API-Design Du definierst fachliche Testfälle, nimmst Features ab, stim… | R30: Ağ / Firewall / VPN, Proje yönetimi, Bütçe, Ekip liderliği, Risk yönetimi | S30: Almanca C1 / çok iyi Almanca | T30: 4.5 | U30: 5 | V30: 1 | W30: 4 | X30: 5 | Y30: 4.5 | Z30: =ROUND((T30*Özet!$C$14+U30*Özet!$C$15+V30*Özet!$C$16+W30*Özet!$C$17+X30*Özet!$C$18+Y30*Özet!$C$19)/5,4) -> 0.71 | AA30: =RANK(AE30,$AE$5:$AE$126)+COUNTIF($AE$5:AE30,AE30)-1 -> 26 | AB30: =IF(AND(OR(G30="EN",G30="EN (+DE artı)"),Z30>=0.7),"A – Hemen başvur (İngilizce)",IF(Z30>=0.7,"B – Başvur (Almanca gerekli)",IF(AND(OR(G30="EN",G30="EN (+DE artı)"),Z30>=0.6),"B – Başvur (İngilizce)","C – Opsiyonel"))) -> B – Başvur (Almanca gerekli) | AC30: Almanca C1 isteniyor – yine de başvurmak istersen Almanca CV + dil planı (kurs/sertifika) belirt | AD30: https://www.karriere.at/f/reqpool | AE30: =Z30+IF(OR(G30="EN",G30="EN (+DE artı)"),1,0) -> 0.71
A31: 27 | B31: KTM AG | C31: Head of IT Infrastructure & Operations* | D31: Mattighofen | E31: 45–60 dk | F31: IT yönetimi / liderlik | G31: DE | H31: İlan Almanca; seviye belirtilmemiş | I31: — | J31: Kıdemli / yönetici | K31: ~€82k+/yıl (ilan: ab 81.500 € jährlich) | L31: 2026-09-26 | M31: karriere.at | N31: https://www.karriere.at/jobs/7852769 | O31: 27.09.2026 14:14 · HTTP 200 · AÇIK | Q31: Mehrjährige Berufs‑ und Führungserfahrung im IT‑Infrastructure‑ und/oder Operations‑Umfeld Fundierte Erfahrung in der Steuerung von operativen IT‑Einheiten, Dienstleistern und komplexen IT‑Betriebsstrukturen Erfahrung mit KPI‑, SLA‑ und Provider‑Management sowie Budget‑ und Vertragsverantwortung Fähigkeit, auch in komplexen oder unsicheren Situationen klare Entscheidungen zu treffen und konsequent umzusetzen Ausgeprä… | R31: Tedarikçi yönetimi, Bütçe, Ekip liderliği | S31: Linux | T31: 4.5 | U31: 5 | V31: 1.5 | W31: 4 | X31: 3 | Y31: 5 | Z31: =ROUND((T31*Özet!$C$14+U31*Özet!$C$15+V31*Özet!$C$16+W31*Özet!$C$17+X31*Özet!$C$18+Y31*Özet!$C$19)/5,4) -> 0.71 | AA31: =RANK(AE31,$AE$5:$AE$126)+COUNTIF($AE$5:AE31,AE31)-1 -> 27 | AB31: =IF(AND(OR(G31="EN",G31="EN (+DE artı)"),Z31>=0.7),"A – Hemen başvur (İngilizce)",IF(Z31>=0.7,"B – Başvur (Almanca gerekli)",IF(AND(OR(G31="EN",G31="EN (+DE artı)"),Z31>=0.6),"B – Başvur (İngilizce)","C – Opsiyonel"))) -> B – Başvur (Almanca gerekli) | AC31: Almanca CV + Anschreiben ile başvur (Almanca B1/B2 belirt) | AD31: https://www.karriere.at/f/ktm | AE31: =Z31+IF(OR(G31="EN",G31="EN (+DE artı)"),1,0) -> 0.71
A32: 28 | B32: ACP Gruppe | C32: Senior Operations Engineer m, w, d | D32: Salzburg | E32: ≤30 dk (Salzburg / yakın çevre) | F32: Sistem / altyapı | G32: DE | H32: İlan Almanca; seviye belirtilmemiş | I32: — | J32: Kıdemli / yönetici | K32: ~€60k+/yıl (ilan: ab 60.000 € jährlich) | L32: 2026-09-24 | M32: karriere.at | N32: https://www.karriere.at/jobs/7818680 | O32: 27.09.2026 14:13 · HTTP 200 · AÇIK | P32: https://bewerbung.acp-gruppe.com/at/rx/1119 | Q32: Analytisches Denken und strukturierte Problemlösung. Verantwortungsbewusstsein und Zuverlässigkeit. Kommunikations‑ und Teamfähigkeit. Sehr gute Kenntnisse im Bereich Hypervisor (VMware und Hyper-V). Sehr gute Kenntnisse im Microsoft Windows Bereich inkl. Rollen & Features. Sehr gute Kenntnisse bei Backup & Restore Systemen (Veeam und CommVault). Gute Netzwerkkenntnisse im Bereich Firewalls (Fortinet und Juniper), Sw… | R32: Windows Server, Sanallaştırma (Hyper-V/Proxmox), Backup / DR, Ağ / Firewall / VPN, Tedarikçi yönetimi, Bütçe, Microsoft ortamı, Perakende / çok lokasyon | S32: VMware, Ağ üreticisi sertifikası (Cisco/Fortinet/Palo Alto) | T32: 4 | U32: 4.5 | V32: 1.5 | W32: 4 | X32: 5 | Y32: 4.5 | Z32: =ROUND((T32*Özet!$C$14+U32*Özet!$C$15+V32*Özet!$C$16+W32*Özet!$C$17+X32*Özet!$C$18+Y32*Özet!$C$19)/5,4) -> 0.695 | AA32: =RANK(AE32,$AE$5:$AE$126)+COUNTIF($AE$5:AE32,AE32)-1 -> 28 | AB32: =IF(AND(OR(G32="EN",G32="EN (+DE artı)"),Z32>=0.7),"A – Hemen başvur (İngilizce)",IF(Z32>=0.7,"B – Başvur (Almanca gerekli)",IF(AND(OR(G32="EN",G32="EN (+DE artı)"),Z32>=0.6),"B – Başvur (İngilizce)","C – Opsiyonel"))) -> C – Opsiyonel | AC32: Almanca CV + Anschreiben ile başvur (Almanca B1/B2 belirt) | AD32: https://www.karriere.at/f/acp-gruppe | AE32: =Z32+IF(OR(G32="EN",G32="EN (+DE artı)"),1,0) -> 0.695
A33: 29 | B33: Senoplast Klepsch & Co GmbH | C33: IT Operations & Security Manager (m/w/d) | D33: Piesendorf | E33: 60–90 dk | F33: Cyber Security – yönetişim / ISMS | G33: DE | H33: İlan Almanca; seviye belirtilmemiş | I33: — | J33: Kıdemli / yönetici | K33: İlanda belirtilmemiş | L33: 2026-08-27 | M33: karriere.at | N33: https://www.karriere.at/jobs/10024962 | O33: 27.09.2026 14:13 · HTTP 200 · AÇIK | Q33: Mehrjährige Berufserfahrung im IT Operations Management, Security Information Management oder in einer kombinierten Rolle Gutes Verständnis von ITIL-orientierten Prozessen, insbesondere in den Bereichen Incident, Problem, Change und Service Management Verständnis für Security Information Management Strukturierte, eigenverantwortliche und ergebnisorientierte Arbeitsweise in einem modernen IT-Umfeld mit Fokus auf Veran… | R33: ISO 27001 / ISMS, ITIL / ITSM, Tedarikçi yönetimi, Perakende / çok lokasyon | S33: Belirgin teknik eksik yok | T33: 5 | U33: 5 | V33: 1.5 | W33: 4 | X33: 2 | Y33: 3.5 | Z33: =ROUND((T33*Özet!$C$14+U33*Özet!$C$15+V33*Özet!$C$16+W33*Özet!$C$17+X33*Özet!$C$18+Y33*Özet!$C$19)/5,4) -> 0.69 | AA33: =RANK(AE33,$AE$5:$AE$126)+COUNTIF($AE$5:AE33,AE33)-1 -> 29 | AB33: =IF(AND(OR(G33="EN",G33="EN (+DE artı)"),Z33>=0.7),"A – Hemen başvur (İngilizce)",IF(Z33>=0.7,"B – Başvur (Almanca gerekli)",IF(AND(OR(G33="EN",G33="EN (+DE artı)"),Z33>=0.6),"B – Başvur (İngilizce)","C – Opsiyonel"))) -> C – Opsiyonel | AC33: Almanca CV + Anschreiben ile başvur (Almanca B1/B2 belirt) | AD33: https://www.karriere.at/f/senoplast-klepsch | AE33: =Z33+IF(OR(G33="EN",G33="EN (+DE artı)"),1,0) -> 0.69
A34: 30 | B34: Arvai Plastics GmbH & CoKG | C34: IT-Systemadministrator (m/w/d) | D34: Neumarkt am Wallersee | E34: 30–45 dk | F34: Sistem / altyapı | G34: DE+EN | H34: Arbeitsweise Teamfähigkeit und Kommunikationsstärke Gute Deutsch- und Englischkenntnisse WIR BIETEN DIR Wachsendes Familienunternehmen | I34: — | J34: Uzman (mid-senior) | K34: Sadece KV asgarisi: ~€34k/yıl (ilan metni) – gerçek maaş belirtilmemiş, genelde üstünde | L34: 2026-09-22 | M34: karriere.at | N34: https://www.karriere.at/jobs/10030515 | O34: 27.09.2026 14:13 · HTTP 200 · AÇIK | Q34: und Berufserfahrungen; mögliche Überzahlungen werden selbstverständlich berücksichtigt. KV Mindestgehalt 2.427,90 EUR Benefits Aus- und Weiterbildung Gute Anbindung Team-Events Aus- und Weiterbildung Gute Anbindung Team-Events Alle Benefits anzeigen Weniger Benefits anzeigen INTERESSIERT? Wenn du eine neue Herausforderung in einem dynamischen Umfeld suchst, dann freuen wir uns auf deine aussagekräftige Bewerbung. Bei… | R34: Windows Server, Sanallaştırma (Hyper-V/Proxmox), Backup / DR, Ağ / Firewall / VPN, Ekip liderliği, Politika / uyum, Perakende / çok lokasyon | S34: Belirgin teknik eksik yok | T34: 4.5 | U34: 4 | V34: 2 | W34: 4 | X34: 4 | Y34: 3 | Z34: =ROUND((T34*Özet!$C$14+U34*Özet!$C$15+V34*Özet!$C$16+W34*Özet!$C$17+X34*Özet!$C$18+Y34*Özet!$C$19)/5,4) -> 0.69 | AA34: =RANK(AE34,$AE$5:$AE$126)+COUNTIF($AE$5:AE34,AE34)-1 -> 30 | AB34: =IF(AND(OR(G34="EN",G34="EN (+DE artı)"),Z34>=0.7),"A – Hemen başvur (İngilizce)",IF(Z34>=0.7,"B – Başvur (Almanca gerekli)",IF(AND(OR(G34="EN",G34="EN (+DE artı)"),Z34>=0.6),"B – Başvur (İngilizce)","C – Opsiyonel"))) -> C – Opsiyonel | AC34: Almanca CV ile başvur; İngilizce yeterliliğini ve Almanca B1/B2'yi açıkça yaz · İletişim: jobs@arvai-plastics.at. | AD34: https://www.karriere.at/f/arvai-plastics | AE34: =Z34+IF(OR(G34="EN",G34="EN (+DE artı)"),1,0) -> 0.69
